Workbook
Name _100X2.5MM_UV_Cable_Tie_Black: 'Master Data'!$Y$4:$Y$74
Name _38x50_OD_DWC_Pipe__500MTR__UV___Anti_Rodent: 'Master Data'!$AM$4:$AM$74
Name _3CX240Sqmm_A2XFY_19_33KV_HT_Cable: 'Master Data'!$L$4:$L$74
Name _3CX240Sqmm_A2XFY_UNSCR_ATR_UV_AF_3.3_KV: 'Master Data'!$K$4:$K$74
Name AC_Cables: 'Master Data'!$K$3:$K$74
Name Assets: 'Master Data'!$G$3:$AR$74
Name Aux_Control_Cable: 'Master Data'!$N$3:$N$74
Name Aux_UPS_Panel: 'Master Data'!$AD$3:$AD$74
Name bala: 'Master Data'!$AO$20:$AO$60
Name Battery: 'Master Data'!$G$3:$G$74
Name Bus_Duct: 'Master Data'!$H$3:$H$74
Name Cable_Glands: 'Master Data'!$T$3:$T$74
Name Cable_Lugs: 'Master Data'!$V$3:$V$74
Name Cable_Route_Marker: 'Master Data'!$X$3:$X$74
Name Cable_Sleeve: 'Master Data'!$W$3:$W$74
Name Cable_Termination_Kit: 'Master Data'!$U$3:$U$74
Name Cable_Tie: 'Master Data'!$Y$3:$Y$74
Name Cable_Tray: 'Master Data'!$I$3:$I$74
Name Cables: 'Master Data'!$N$3:$N$74
Name Catagory: 'Master Data'!$B$3:$B$10
Name CCTV: 'Master Data'!$P$3:$P$74
Name Civil: 'Master Data'!$Q$3:$Q$74
Name Column_C_120x50x15x1493x2mm_Thick: 'Master Data'!$AJ$4:$AJ$60
Name Column_Post___140x50x20x2.0_MM: 'Master Data'!$AJ$4:$AJ$74
Name Communication_Cable: 'Master Data'!$O$3:$O$74
Name Conductors: 'Master Data'!$R$3:$R$74
Name Connectors: 'Master Data'!$S$3:$S$74
Name Control_Cable: 'Master Data'!$V$3:$V$74
Name CT___PT: 'Master Data'!#REF!
Name CT_PT: 'Master Data'!#REF!
Name DC_Cable: 'Master Data'!$J$4:$J$74
Name DC_Cables: 'Master Data'!$J$3:$J$74
Name Earthing: 'Master Data'!$AE$3:$AE$74
Name Earthing_cables: 'Master Data'!$M$3:$M$74
Name Earthing_Strip: 'Master Data'!$AE$4:$AE$74
Name ESE_Train: 'Master Data'!$AH$4:$AH$74
Name Fencing: 'Master Data'!$AF$3:$AF$74
Name Gland: 'Master Data'!#REF!
Name HEX_BOLT_NUT_2PLN_WSR_1SP_WSR_M_16x40: 'Master Data'!$AK$4:$AK$74
Name HT_Cables: 'Master Data'!$L$3:$L$74
Name HT_Panel: 'Master Data'!$AB$3:$AB$74
Name Inverter: 'Master Data'!$Z$3:$Z$74
Name Inverter_Column_Post__ISMC___100x50x5mm___3000mmL: 'Master Data'!$AG$4:$AG$74
Name Inverters: 'Master Data'!$AG$3:$AG$74
Name Inverters_Structure: 'Master Data'!$AG$3:$AG$74
Name Lighting_arrestor: 'Master Data'!$AH$3:$AH$74
Name Location: 'Master Data'!$B$32:$B$38
Name LT_Panel: 'Master Data'!$AC$3:$AC$74
Name M16x40mm_B_N_2PW_1SW_HDG_8.8: 'Master Data'!$AK$4:$AK$60
Name MCS: 'Master Data'!$R$3:$R$74
Name MMS_Fasteners: 'Master Data'!$AK$3:$AK$74
Name Module_Mounting_Structure: 'Master Data'!$AJ$3:$AJ$74
Name NIFPS: 'Master Data'!$AL$3:$AL$74
Name Others: 'Master Data'!$AP$3:$AP$74
Name Pipes: 'Master Data'!$AM$3:$AM$74
Name Price: 'Master Data'!$D$15:$D$16
Name Safety_Equipments: 'Master Data'!$AO$3:$AO$74
Name Sand_Bucket_With_Stend__canopy: 'Master Data'!$AO$4:$AO$74
Name Scada: 'Master Data'!$AR$3:$AR$74
Name Solar_Modules: 'Master Data'!$AN$3:$AN$74

Sheet Recon-Statement
A2: DATE | B2: =TODAY() -> 45634 | E2: BOQ VS RECEIVED | J2: RECEIVED VS STOCK
A3: S.No | B3: Item Description | C3: Make / Vendor | D3: Unit | E3: BOQ | F3: Received | G3: Yet to Receive | H3: Excess Received | I3: Column3 | J3: Received. | K3: Issued | L3: Theoretical Stock | M3: Column32 | N3: Remarks
A4: =BOQ[[#This Row],[S.No]] -> A | B4: =BOQ[[#This Row],[Item Description]] -> Module_Mounting_Structure | C4: =BOQ[[#This Row],[Make / Vendor]] -> 0 | D4: =BOQ[[#This Row],[Unit]] -> 0 | F4: =SUMIF('Goods Receipt'!$J:$J,Over_all[[#This Row],[Item Description]],'Goods Receipt'!$M:$M) -> 0 | H4: =IF(Over_all[[#This Row],[BOQ]]-Over_all[[#This Row],[Received]]<0,Over_all[[#This Row],[BOQ]]-Over_all[[#This Row],[Received]],"") | K4: =SUMIF(ISSUE!$F:$F,Over_all[[#This Row],[Item Description]],ISSUE!$I:$I) -> 0 | L4: =Over_all[[#This Row],[Received.]]-Over_all[[#This Row],[Issued]] -> 0
A5: =BOQ[[#This Row],[S.No]] -> 1 | B5: =BOQ[[#This Row],[Item Description]] -> Column Post - 120x50x20x2.0 MM | C5: =BOQ[[#This Row],[Make / Vendor]] -> 0 | D5: =BOQ[[#This Row],[Unit]] -> Nos | E5: =BOQ[[#This Row],[BOQ]] -> 4434 | F5: =SUMIF('Goods Receipt'!$J:$J,Over_all[[#This Row],[Item Description]],'Goods Receipt'!$M:$M) -> 4493 | G5: =IF(Over_all[[#This Row],[BOQ]]-Over_all[[#This Row],[Received]]>=0,Over_all[[#This Row],[BOQ]]-Over_all[[#This Row],[Received]],"") | H5: =IF(Over_all[[#This Row],[BOQ]]-Over_all[[#This Row],[Received]]<0,Over_all[[#This Row],[BOQ]]-Over_all[[#This Row],[Received]],"") -> -59 | J5: =Over_all[[#This Row],[Received]] -> 4493 | K5: =SUMIF(ISSUE!$F:$F,Over_all[[#This Row],[Item Description]],ISSUE!$I:$I) -> 2549 | L5: =Over_all[[#This Row],[Received.]]-Over_all[[#This Row],[Issued]] -> 1944
A6: =BOQ[[#This Row],[S.No]] -> 2 | B6: =BOQ[[#This Row],[Item Description]] -> Column Ext - 50x50x2.0 MM | C6: =BOQ[[#This Row],[Make / Vendor]] -> 0 | D6: =BOQ[[#This Row],[Unit]] -> Nos | E6: =BOQ[[#This Row],[BOQ]] -> 4434 | F6: =SUMIF('Goods Receipt'!$J:$J,Over_all[[#This Row],[Item Description]],'Goods Receipt'!$M:$M) -> 4409 | G6: =IF(Over_all[[#This Row],[BOQ]]-Over_all[[#This Row],[Received]]>=0,Over_all[[#This Row],[BOQ]]-Over_all[[#This Row],[Received]],"") -> 25 | H6: =IF(Over_all[[#This Row],[BOQ]]-Over_all[[#This Row],[Received]]<0,Over_all[[#This Row],[BOQ]]-Over_all[[#This Row],[Received]],"") | J6: =Over_all[[#This Row],[Received]] -> 4409 | K6: =SUMIF(ISSUE!$F:$F,Over_all[[#This Row],[Item Description]],ISSUE!$I:$I) -> 2528 | L6: =Over_all[[#This Row],[Received.]]-Over_all[[#This Row],[Issued]] -> 1881
A7: =BOQ[[#This Row],[S.No]] -> 3 | B7: =BOQ[[#This Row],[Item Description]] -> Module Mounting Strucyure - Purlin (P1) | C7: =BOQ[[#This Row],[Make / Vendor]] -> 0 | D7: =BOQ[[#This Row],[Unit]] -> Nos | E7: =BOQ[[#This Row],[BOQ]] -> 5912 | F7: =SUMIF('Goods Receipt'!$J:$J,Over_all[[#This Row],[Item Description]],'Goods Receipt'!$M:$M) -> 5990 | G7: =IF(Over_all[[#This Row],[BOQ]]-Over_all[[#This Row],[Received]]>=0,Over_all[[#This Row],[BOQ]]-Over_all[[#This Row],[Received]],"") | H7: =IF(Over_all[[#This Row],[BOQ]]-Over_all[[#This Row],[Received]]<0,Over_all[[#This Row],[BOQ]]-Over_all[[#This Row],[Received]],"") -> -78 | J7: =Over_all[[#This Row],[Received]] -> 5990 | K7: =SUMIF(ISSUE!$F:$F,Over_all[[#This Row],[Item Description]],ISSUE!$I:$I) -> 0 | L7: =Over_all[[#This Row],[Received.]]-Over_all[[#This Row],[Issued]] -> 5990
A8: =BOQ[[#This Row],[S.No]] -> 4 | B8: =BOQ[[#This Row],[Item Description]] -> Module Mounting Strucyure - Rafter | C8: =BOQ[[#This Row],[Make / Vendor]] -> 0 | D8: =BOQ[[#This Row],[Unit]] -> Nos | E8: =BOQ[[#This Row],[BOQ]] -> 4434 | F8: =SUMIF('Goods Receipt'!$J:$J,Over_all[[#This Row],[Item Description]],'Goods Receipt'!$M:$M) -> 4488 | G8: =IF(Over_all[[#This Row],[BOQ]]-Over_all[[#This Row],[Received]]>=0,Over_all[[#This Row],[BOQ]]-Over_all[[#This Row],[Received]],"") | H8: =IF(Over_all[[#This Row],[BOQ]]-Over_all[[#This Row],[Received]]<0,Over_all[[#This Row],[BOQ]]-Over_all[[#This Row],[Received]],"") -> -54 | J8: =Over_all[[#This Row],[Received]] -> 4488 | K8: =SUMIF(ISSUE!$F:$F,Over_all[[#This Row],[Item Description]],ISSUE!$I:$I) -> 1090 | L8: =Over_all[[#This Row],[Received.]]-Over_all[[#This Row],[Issued]] -> 3398
A9: =BOQ[[#This Row],[S.No]] -> 5 | B9: =BOQ[[#This Row],[Item Description]] -> Module Mounting Strucyure - Rafter Bracing Back | C9: =BOQ[[#This Row],[Make / Vendor]] -> 0 | D9: =BOQ[[#This Row],[Unit]] -> Nos | E9: =BOQ[[#This Row],[BOQ]] -> 4434 | F9: =SUMIF('Goods Receipt'!$J:$J,Over_all[[#This Row],[Item Description]],'Goods Receipt'!$M:$M) -> 4494 | G9: =IF(Over_all[[#This Row],[BOQ]]-Over_all[[#This Row],[Received]]>=0,Over_all[[#This Row],[BOQ]]-Over_all[[#This Row],[Received]],"") | H9: =IF(Over_all[[#This Row],[BOQ]]-Over_all[[#This Row],[Received]]<0,Over_all[[#This Row],[BOQ]]-Over_all[[#This Row],[Received]],"") -> -60 | J9: =Over_all[[#This Row],[Received]] -> 4494 | K9: =SUMIF(ISSUE!$F:$F,Over_all[[#This Row],[Item Description]],ISSUE!$I:$I) -> 1090 | L9: =Over_all[[#This Row],[Received.]]-Over_all[[#This Row],[Issued]] -> 3404
A10: =BOQ[[#This Row],[S.No]] -> 6 | B10: =BOQ[[#This Row],[Item Description]] -> Module Mounting Strucyure - Bracing Connector | C10: =BOQ[[#This Row],[Make / Vendor]] -> 0 | D10: =BOQ[[#This Row],[Unit]] -> Nos | E10: =BOQ[[#This Row],[BOQ]] -> 4434 | F10: =SUMIF('Goods Receipt'!$J:$J,Over_all[[#This Row],[Item Description]],'Goods Receipt'!$M:$M) -> 4536 | G10: =IF(Over_all[[#This Row],[BOQ]]-Over_all[[#This Row],[Received]]>=0,Over_all[[#This Row],[BOQ]]-Over_all[[#This Row],[Received]],"") | H10: =IF(Over_all[[#This Row],[BOQ]]-Over_all[[#This Row],[Received]]<0,Over_all[[#This Row],[BOQ]]-Over_all[[#This Row],[Received]],"") -> -102 | J10: =Over_all[[#This Row],[Received]] -> 4536 | K10: =SUMIF(ISSUE!$F:$F,Over_all[[#This Row],[Item Description]],ISSUE!$I:$I) -> 0 | L10: =Over_all[[#This Row],[Received.]]-Over_all[[#This Row],[Issued]] -> 4536
A11: =BOQ[[#This Row],[S.No]] -> 7 | B11: =BOQ[[#This Row],[Item Description]] -> Module Mounting Strucyure - Purlin (P2) | C11: =BOQ[[#This Row],[Make / Vendor]] -> 0 | D11: =BOQ[[#This Row],[Unit]] -> Nos | E11: =BOQ[[#This Row],[BOQ]] -> 2956 | F11: =SUMIF('Goods Receipt'!$J:$J,Over_all[[#This Row],[Item Description]],'Goods Receipt'!$M:$M) -> 2995 | G11: =IF(Over_all[[#This Row],[BOQ]]-Over_all[[#This Row],[Received]]>=0,Over_all[[#This Row],[BOQ]]-Over_all[[#This Row],[Received]],"") | H11: =IF(Over_all[[#This Row],[BOQ]]-Over_all[[#This Row],[Received]]<0,Over_all[[#This Row],[BOQ]]-Over_all[[#This Row],[Received]],"") -> -39 | J11: =Over_all[[#This Row],[Received]] -> 2995 | K11: =SUMIF(ISSUE!$F:$F,Over_all[[#This Row],[Item Description]],ISSUE!$I:$I) -> 0 | L11: =Over_all[[#This Row],[Received.]]-Over_all[[#This Row],[Issued]] -> 2995
A12: =BOQ[[#This Row],[S.No]] -> 8 | B12: =BOQ[[#This Row],[Item Description]] -> Module Mounting Strucyure - Col, to Rafter Bracing front | C12: =BOQ[[#This Row],[Make / Vendor]] -> 0 | D12: =BOQ[[#This Row],[Unit]] -> Nos | E12: =BOQ[[#This Row],[BOQ]] -> 4434 | F12: =SUMIF('Goods Receipt'!$J:$J,Over_all[[#This Row],[Item Description]],'Goods Receipt'!$M:$M) -> 4200 | G12: =IF(Over_all[[#This Row],[BOQ]]-Over_all[[#This Row],[Received]]>=0,Over_all[[#This Row],[BOQ]]-Over_all[[#This Row],[Received]],"") -> 234 | H12: =IF(Over_all[[#This Row],[BOQ]]-Over_all[[#This Row],[Received]]<0,Over_all[[#This Row],[BOQ]]-Over_all[[#This Row],[Received]],"") | J12: =Over_all[[#This Row],[Received]] -> 4200 | K12: =SUMIF(ISSUE!$F:$F,Over_all[[#This Row],[Item Description]],ISSUE!$I:$I) -> 1090 | L12: =Over_all[[#This Row],[Received.]]-Over_all[[#This Row],[Issued]] -> 3110
A13: =BOQ[[#This Row],[S.No]] -> 9 | B13: =BOQ[[#This Row],[Item Description]] -> Module Mounting Strucyure - Stay Bracing | C13: =BOQ[[#This Row],[Make / Vendor]] -> 0 | D13: =BOQ[[#This Row],[Unit]] -> Nos | E13: =BOQ[[#This Row],[BOQ]] -> 1478 | F13: =SUMIF('Goods Receipt'!$J:$J,Over_all[[#This Row],[Item Description]],'Goods Receipt'!$M:$M) -> 1498 | G13: =IF(Over_all[[#This Row],[BOQ]]-Over_all[[#This Row],[Received]]>=0,Over_all[[#This Row],[BOQ]]-Over_all[[#This Row],[Received]],"") | H13: =IF(Over_all[[#This Row],[BOQ]]-Over_all[[#This Row],[Received]]<0,Over_all[[#This Row],[BOQ]]-Over_all[[#This Row],[Received]],"") -> -20 | J13: =Over_all[[#This Row],[Received]] -> 1498 | K13: =SUMIF(ISSUE!$F:$F,Over_all[[#This Row],[Item Description]],ISSUE!$I:$I) -> 0 | L13: =Over_all[[#This Row],[Received.]]-Over_all[[#This Row],[Issued]] -> 1498
A14: =BOQ[[#This Row],[S.No]] -> 0 | B14: =BOQ[[#This Row],[Item Description]] -> 0 | C14: =BOQ[[#This Row],[Make / Vendor]] -> 0 | D14: =BOQ[[#This Row],[Unit]] -> 0 | E14: =BOQ[[#This Row],[BOQ]] -> 0 | F14: =SUMIF('Goods Receipt'!$J:$J,Over_all[[#This Row],[Item Description]],'Goods Receipt'!$M:$M) -> 0 | G14: =IF(Over_all[[#This Row],[BOQ]]-Over_all[[#This Row],[Received]]>=0,Over_all[[#This Row],[BOQ]]-Over_all[[#This Row],[Received]],"") -> 0 | H14: =IF(Over_all[[#This Row],[BOQ]]-Over_all[[#This Row],[Received]]<0,Over_all[[#This Row],[BOQ]]-Over_all[[#This Row],[Received]],"") | J14: =Over_all[[#This Row],[Received]] -> 0 | K14: =SUMIF(ISSUE!$F:$F,Over_all[[#This Row],[Item Description]],ISSUE!$I:$I) -> 0 | L14: =Over_all[[#This Row],[Received.]]-Over_all[[#This Row],[Issued]] -> 0
A15: =BOQ[[#This Row],[S.No]] -> B | B15: =BOQ[[#This Row],[Item Description]] -> MMS_Fasteners | C15: =BOQ[[#This Row],[Make / Vendor]] -> 0 | D15: =BOQ[[#This Row],[Unit]] -> 0 | E15: =BOQ[[#This Row],[BOQ]] -> 0 | F15: =SUMIF('Goods Receipt'!$J:$J,Over_all[[#This Row],[Item Description]],'Goods Receipt'!$M:$M) -> 0 | G15: =IF(Over_all[[#This Row],[BOQ]]-Over_all[[#This Row],[Received]]>=0,Over_all[[#This Row],[BOQ]]-Over_all[[#This Row],[Received]],"") -> 0 | H15: =IF(Over_all[[#This Row],[BOQ]]-Over_all[[#This Row],[Received]]<0,Over_all[[#This Row],[BOQ]]-Over_all[[#This Row],[Received]],"") | J15: =Over_all[[#This Row],[Received]] -> 0 | K15: =SUMIF(ISSUE!$F:$F,Over_all[[#This Row],[Item Description]],ISSUE!$I:$I) -> 0 | L15: =Over_all[[#This Row],[Received.]]-Over_all[[#This Row],[Issued]] -> 0
A16: =BOQ[[#This Row],[S.No]] -> 1 | B16: =BOQ[[#This Row],[Item Description]] -> HEX BOLT+NUT+2PLN WSR+1SP WSR M-16x40 | C16: =BOQ[[#This Row],[Make / Vendor]] -> 0 | D16: =BOQ[[#This Row],[Unit]] -> Set | E16: =BOQ[[#This Row],[BOQ]] -> 4434 | F16: =SUMIF('Goods Receipt'!$J:$J,Over_all[[#This Row],[Item Description]],'Goods Receipt'!$M:$M) -> 4290 | G16: =IF(Over_all[[#This Row],[BOQ]]-Over_all[[#This Row],[Received]]>=0,Over_all[[#This Row],[BOQ]]-Over_all[[#This Row],[Received]],"") -> 144 | H16: =IF(Over_all[[#This Row],[BOQ]]-Over_all[[#This Row],[Received]]<0,Over_all[[#This Row],[BOQ]]-Over_all[[#This Row],[Received]],"") | J16: =Over_all[[#This Row],[Received]] -> 4290 | K16: =SUMIF(ISSUE!$F:$F,Over_all[[#This Row],[Item Description]],ISSUE!$I:$I) -> 2000 | L16: =Over_all[[#This Row],[Received.]]-Over_all[[#This Row],[Issued]] -> 2290
... A26: =BOQ[[#This Row],[S.No]] -> 0 | B26: =BOQ[[#This Row],[Item Description]] -> 0 | C26: =BOQ[[#This Row],[Make / Vendor]] -> 0 | D26: =BOQ[[#This Row],[Unit]] -> 0 | E26: =BOQ[[#This Row],[BOQ]] -> 0 | F26: =SUMIF('Goods Receipt'!$J:$J,Over_all[[#This Row],[Item Description]],'Goods Receipt'!$M:$M) -> 0 | G26: =IF(Over_all[[#This Row],[BOQ]]-Over_all[[#This Row],[Received]]>=0,Over_all[[#This Row],[BOQ]]-Over_all[[#This Row],[Received]],"") -> 0 | H26: =IF(Over_all[[#This Row],[BOQ]]-Over_all[[#This Row],[Received]]<0,Over_all[[#This Row],[BOQ]]-Over_all[[#This Row],[Received]],"") | J26: =Over_all[[#This Row],[Received]] -> 0 | K26: =SUMIF(ISSUE!$F:$F,Over_all[[#This Row],[Item Description]],ISSUE!$I:$I) -> 0 | L26: =Over_all[[#This Row],[Received.]]-Over_all[[#This Row],[Issued]] -> 0
A27: =BOQ[[#This Row],[S.No]] -> C | B27: =BOQ[[#This Row],[Item Description]] -> Solar_Modules | C27: =BOQ[[#This Row],[Make / Vendor]] -> 0 | D27: Nos | E27: 20692 | F27: =SUMIF('Goods Receipt'!$J:$J,Over_all[[#This Row],[Item Description]],'Goods Receipt'!$M:$M) -> 0 | G27: =IF(Over_all[[#This Row],[BOQ]]-Over_all[[#This Row],[Received]]>=0,Over_all[[#This Row],[BOQ]]-Over_all[[#This Row],[Received]],"") -> 20692 | H27: =IF(Over_all[[#This Row],[BOQ]]-Over_all[[#This Row],[Received]]<0,Over_all[[#This Row],[BOQ]]-Over_all[[#This Row],[Received]],"") | J27: =Over_all[[#This Row],[Received]] -> 0 | K27: =SUMIF(ISSUE!$F:$F,Over_all[[#This Row],[Item Description]],ISSUE!$I:$I) -> 0 | L27: =Over_all[[#This Row],[Received.]]-Over_all[[#This Row],[Issued]] -> 0
A28: =BOQ[[#This Row],[S.No]] -> 0 | B28: =BOQ[[#This Row],[Item Description]] -> 0 | C28: =BOQ[[#This Row],[Make / Vendor]] -> 0 | F28: =SUMIF('Goods Receipt'!$J:$J,Over_all[[#This Row],[Item Description]],'Goods Receipt'!$M:$M) -> 0 | G28: =IF(Over_all[[#This Row],[BOQ]]-Over_all[[#This Row],[Received]]>=0,Over_all[[#This Row],[BOQ]]-Over_all[[#This Row],[Received]],"") -> 0 | H28: =IF(Over_all[[#This Row],[BOQ]]-Over_all[[#This Row],[Received]]<0,Over_all[[#This Row],[BOQ]]-Over_all[[#This Row],[Received]],"") | J28: =Over_all[[#This Row],[Received]] -> 0 | K28: =SUMIF(ISSUE!$F:$F,Over_all[[#This Row],[Item Description]],ISSUE!$I:$I) -> 0 | L28: =Over_all[[#This Row],[Received.]]-Over_all[[#This Row],[Issued]] -> 0
A29: =BOQ[[#This Row],[S.No]] -> D | B29: =BOQ[[#This Row],[Item Description]] -> Cables | C29: =BOQ[[#This Row],[Make / Vendor]] -> 0 | D29: =BOQ[[#This Row],[Unit]] -> 0 | E29: =BOQ[[#This Row],[BOQ]] -> 0 | F29: =SUMIF('Goods Receipt'!$J:$J,Over_all[[#This Row],[Item Description]],'Goods Receipt'!$M:$M) -> 0 | G29: =IF(Over_all[[#This Row],[BOQ]]-Over_all[[#This Row],[Received]]>=0,Over_all[[#This Row],[BOQ]]-Over_all[[#This Row],[Received]],"") -> 0 | H29: =IF(Over_all[[#This Row],[BOQ]]-Over_all[[#This Row],[Received]]<0,Over_all[[#This Row],[BOQ]]-Over_all[[#This Row],[Received]],"") | J29: =Over_all[[#This Row],[Received]] -> 0 | K29: =SUMIF(ISSUE!$F:$F,Over_all[[#This Row],[Item Description]],ISSUE!$I:$I) -> 0 | L29: =Over_all[[#This Row],[Received.]]-Over_all[[#This Row],[Issued]] -> 0
A30: =BOQ[[#This Row],[S.No]] -> D.1 | B30: =BOQ[[#This Row],[Item Description]] -> DC_Cables | C30: =BOQ[[#This Row],[Make / Vendor]] -> 0 | D30: =BOQ[[#This Row],[Unit]] -> 0 | E30: =BOQ[[#This Row],[BOQ]] -> 0 | F30: =SUMIF('Goods Receipt'!$J:$J,Over_all[[#This Row],[Item Description]],'Goods Receipt'!$M:$M) -> 0 | G30: =IF(Over_all[[#This Row],[BOQ]]-Over_all[[#This Row],[Received]]>=0,Over_all[[#This Row],[BOQ]]-Over_all[[#This Row],[Received]],"") -> 0 | H30: =IF(Over_all[[#This Row],[BOQ]]-Over_all[[#This Row],[Received]]<0,Over_all[[#This Row],[BOQ]]-Over_all[[#This Row],[Received]],"") | J30: =Over_all[[#This Row],[Received]] -> 0 | K30: =SUMIF(ISSUE!$F:$F,Over_all[[#This Row],[Item Description]],ISSUE!$I:$I) -> 0 | L30: =Over_all[[#This Row],[Received.]]-Over_all[[#This Row],[Issued]] -> 0
A31: =BOQ[[#This Row],[S.No]] -> 1 | B31: =BOQ[[#This Row],[Item Description]] -> 1CX6Sqmm DC Cable Black | C31: =BOQ[[#This Row],[Make / Vendor]] -> 0 | D31: =BOQ[[#This Row],[Unit]] -> Mtr | E31: =BOQ[[#This Row],[BOQ]] -> 17000 | F31: =SUMIF('Goods Receipt'!$J:$J,Over_all[[#This Row],[Item Description]],'Goods Receipt'!$M:$M) -> 18582 | G31: =IF(Over_all[[#This Row],[BOQ]]-Over_all[[#This Row],[Received]]>=0,Over_all[[#This Row],[BOQ]]-Over_all[[#This Row],[Received]],"") | H31: =IF(Over_all[[#This Row],[BOQ]]-Over_all[[#This Row],[Received]]<0,Over_all[[#This Row],[BOQ]]-Over_all[[#This Row],[Received]],"") -> -1582 | J31: =Over_all[[#This Row],[Received]] -> 18582 | K31: =SUMIF(ISSUE!$F:$F,Over_all[[#This Row],[Item Description]],ISSUE!$I:$I) -> 16082 | L31: =Over_all[[#This Row],[Received.]]-Over_all[[#This Row],[Issued]] -> 2500
A32: =BOQ[[#This Row],[S.No]] -> 2 | B32: =BOQ[[#This Row],[Item Description]] -> 1CX6Sqmm DC Cable Red | C32: =BOQ[[#This Row],[Make / Vendor]] -> 0 | D32: =BOQ[[#This Row],[Unit]] -> Mtr | E32: =BOQ[[#This Row],[BOQ]] -> 17000 | F32: =SUMIF('Goods Receipt'!$J:$J,Over_all[[#This Row],[Item Description]],'Goods Receipt'!$M:$M) -> 21199 | G32: =IF(Over_all[[#This Row],[BOQ]]-Over_all[[#This Row],[Received]]>=0,Over_all[[#This Row],[BOQ]]-Over_all[[#This Row],[Received]],"") | H32: =IF(Over_all[[#This Row],[BOQ]]-Over_all[[#This Row],[Received]]<0,Over_all[[#This Row],[BOQ]]-Over_all[[#This Row],[Received]],"") -> -4199 | J32: =Over_all[[#This Row],[Received]] -> 21199 | K32: =SUMIF(ISSUE!$F:$F,Over_all[[#This Row],[Item Description]],ISSUE!$I:$I) -> 16107 | L32: =Over_all[[#This Row],[Received.]]-Over_all[[#This Row],[Issued]] -> 5092
A33: =BOQ[[#This Row],[S.No]] -> 0 | B33: =BOQ[[#This Row],[Item Description]] -> 0 | C33: =BOQ[[#This Row],[Make / Vendor]] -> 0 | D33: =BOQ[[#This Row],[Unit]] -> 0 | E33: =BOQ[[#This Row],[BOQ]] -> 0 | F33: =SUMIF('Goods Receipt'!$J:$J,Over_all[[#This Row],[Item Description]],'Goods Receipt'!$M:$M) -> 0 | G33: =IF(Over_all[[#This Row],[BOQ]]-Over_all[[#This Row],[Received]]>=0,Over_all[[#This Row],[BOQ]]-Over_all[[#This Row],[Received]],"") -> 0 | H33: =IF(Over_all[[#This Row],[BOQ]]-Over_all[[#This Row],[Received]]<0,Over_all[[#This Row],[BOQ]]-Over_all[[#This Row],[Received]],"") | J33: =Over_all[[#This Row],[Received]] -> 0 | K33: =SUMIF(ISSUE!$F:$F,Over_all[[#This Row],[Item Description]],ISSUE!$I:$I) -> 0 | L33: =Over_all[[#This Row],[Received.]]-Over_all[[#This Row],[Issued]] -> 0
A34: =BOQ[[#This Row],[S.No]] -> D.2 | B34: =BOQ[[#This Row],[Item Description]] -> AC_Cables | C34: =BOQ[[#This Row],[Make / Vendor]] -> 0 | D34: =BOQ[[#This Row],[Unit]] -> 0 | E34: =BOQ[[#This Row],[BOQ]] -> 0 | F34: =SUMIF('Goods Receipt'!$J:$J,Over_all[[#This Row],[Item Description]],'Goods Receipt'!$M:$M) -> 0 | G34: =IF(Over_all[[#This Row],[BOQ]]-Over_all[[#This Row],[Received]]>=0,Over_all[[#This Row],[BOQ]]-Over_all[[#This Row],[Received]],"") -> 0 | H34: =IF(Over_all[[#This Row],[BOQ]]-Over_all[[#This Row],[Received]]<0,Over_all[[#This Row],[BOQ]]-Over_all[[#This Row],[Received]],"") | J34: =Over_all[[#This Row],[Received]] -> 0 | K34: =SUMIF(ISSUE!$F:$F,Over_all[[#This Row],[Item Description]],ISSUE!$I:$I) -> 0 | L34: =Over_all[[#This Row],[Received.]]-Over_all[[#This Row],[Issued]] -> 0
A35: =BOQ[[#This Row],[S.No]] -> 1 | B35: =BOQ[[#This Row],[Item Description]] -> 3CX240Sqmm A2XFY UNSCR ATR UV AF 3.3 KV | C35: =BOQ[[#This Row],[Make / Vendor]] -> 0 | D35: =BOQ[[#This Row],[Unit]] -> Mtr | E35: =BOQ[[#This Row],[BOQ]] -> 9500 | F35: =SUMIF('Goods Receipt'!$J:$J,Over_all[[#This Row],[Item Description]],'Goods Receipt'!$M:$M) -> 12066 | G35: =IF(Over_all[[#This Row],[BOQ]]-Over_all[[#This Row],[Received]]>=0,Over_all[[#This Row],[BOQ]]-Over_all[[#This Row],[Received]],"") | H35: =IF(Over_all[[#This Row],[BOQ]]-Over_all[[#This Row],[Received]]<0,Over_all[[#This Row],[BOQ]]-Over_all[[#This Row],[Received]],"") -> -2566 | J35: =Over_all[[#This Row],[Received]] -> 12066 | K35: =SUMIF(ISSUE!$F:$F,Over_all[[#This Row],[Item Description]],ISSUE!$I:$I) -> 8045 | L35: =Over_all[[#This Row],[Received.]]-Over_all[[#This Row],[Issued]] -> 4021
A36: =BOQ[[#This Row],[S.No]] -> 0 | B36: =BOQ[[#This Row],[Item Description]] -> 0 | C36: =BOQ[[#This Row],[Make / Vendor]] -> 0 | D36: =BOQ[[#This Row],[Unit]] -> 0 | E36: =BOQ[[#This Row],[BOQ]] -> 0 | F36: =SUMIF('Goods Receipt'!$J:$J,Over_all[[#This Row],[Item Description]],'Goods Receipt'!$M:$M) -> 0 | G36: =IF(Over_all[[#This Row],[BOQ]]-Over_all[[#This Row],[Received]]>=0,Over_all[[#This Row],[BOQ]]-Over_all[[#This Row],[Received]],"") -> 0 | H36: =IF(Over_all[[#This Row],[BOQ]]-Over_all[[#This Row],[Received]]<0,Over_all[[#This Row],[BOQ]]-Over_all[[#This Row],[Received]],"") | J36: =Over_all[[#This Row],[Received]] -> 0 | K36: =SUMIF(ISSUE!$F:$F,Over_all[[#This Row],[Item Description]],ISSUE!$I:$I) -> 0 | L36: =Over_all[[#This Row],[Received.]]-Over_all[[#This Row],[Issued]] -> 0
A37: =BOQ[[#This Row],[S.No]] -> D.3 | B37: =BOQ[[#This Row],[Item Description]] -> HT_Cables | C37: =BOQ[[#This Row],[Make / Vendor]] -> 0 | D37: =BOQ[[#This Row],[Unit]] -> 0 | E37: =BOQ[[#This Row],[BOQ]] -> 0 | F37: =SUMIF('Goods Receipt'!$J:$J,Over_all[[#This Row],[Item Description]],'Goods Receipt'!$M:$M) -> 0 | G37: =IF(Over_all[[#This Row],[BOQ]]-Over_all[[#This Row],[Received]]>=0,Over_all[[#This Row],[BOQ]]-Over_all[[#This Row],[Received]],"") -> 0 | H37: =IF(Over_all[[#This Row],[BOQ]]-Over_all[[#This Row],[Received]]<0,Over_all[[#This Row],[BOQ]]-Over_all[[#This Row],[Received]],"") | J37: =Over_all[[#This Row],[Received]] -> 0 | K37: =SUMIF(ISSUE!$F:$F,Over_all[[#This Row],[Item Description]],ISSUE!$I:$I) -> 0 | L37: =Over_all[[#This Row],[Received.]]-Over_all[[#This Row],[Issued]] -> 0
A38: =BOQ[[#This Row],[S.No]] -> 1 | B38: =BOQ[[#This Row],[Item Description]] -> 3CX240Sqmm A2XFY 19/33KV HT Cable | C38: =BOQ[[#This Row],[Make / Vendor]] -> 0 | D38: =BOQ[[#This Row],[Unit]] -> Mtr | E38: =BOQ[[#This Row],[BOQ]] -> 1400 | F38: =SUMIF('Goods Receipt'!$J:$J,Over_all[[#This Row],[Item Description]],'Goods Receipt'!$M:$M) -> 1512 | G38: =IF(Over_all[[#This Row],[BOQ]]-Over_all[[#This Row],[Received]]>=0,Over_all[[#This Row],[BOQ]]-Over_all[[#This Row],[Received]],"") | H38: =IF(Over_all[[#This Row],[BOQ]]-Over_all[[#This Row],[Received]]<0,Over_all[[#This Row],[BOQ]]-Over_all[[#This Row],[Received]],"") -> -112 | J38: =Over_all[[#This Row],[Received]] -> 1512 | K38: =SUMIF(ISSUE!$F:$F,Over_all[[#This Row],[Item Description]],ISSUE!$I:$I) -> 0 | L38: =Over_all[[#This Row],[Received.]]-Over_all[[#This Row],[Issued]] -> 1512
A39: =BOQ[[#This Row],[S.No]] -> 0 | B39: =BOQ[[#This Row],[Item Description]] -> 0 | C39: =BOQ[[#This Row],[Make / Vendor]] -> 0 | D39: =BOQ[[#This Row],[Unit]] -> 0 | E39: =BOQ[[#This Row],[BOQ]] -> 0 | F39: =SUMIF('Goods Receipt'!$J:$J,Over_all[[#This Row],[Item Description]],'Goods Receipt'!$M:$M) -> 0 | G39: =IF(Over_all[[#This Row],[BOQ]]-Over_all[[#This Row],[Received]]>=0,Over_all[[#This Row],[BOQ]]-Over_all[[#This Row],[Received]],"") -> 0 | H39: =IF(Over_all[[#This Row],[BOQ]]-Over_all[[#This Row],[Received]]<0,Over_all[[#This Row],[BOQ]]-Over_all[[#This Row],[Received]],"") | J39: =Over_all[[#This Row],[Received]] -> 0 | K39: =SUMIF(ISSUE!$F:$F,Over_all[[#This Row],[Item Description]],ISSUE!$I:$I) -> 0 | L39: =Over_all[[#This Row],[Received.]]-Over_all[[#This Row],[Issued]] -> 0
A40: =BOQ[[#This Row],[S.No]] -> D.4 | B40: =BOQ[[#This Row],[Item Description]] -> Earthing_cables | C40: =BOQ[[#This Row],[Make / Vendor]] -> 0 | D40: =BOQ[[#This Row],[Unit]] -> 0 | E40: =BOQ[[#This Row],[BOQ]] -> 0 | F40: =SUMIF('Goods Receipt'!$J:$J,Over_all[[#This Row],[Item Description]],'Goods Receipt'!$M:$M) -> 0 | G40: =IF(Over_all[[#This Row],[BOQ]]-Over_all[[#This Row],[Received]]>=0,Over_all[[#This Row],[BOQ]]-Over_all[[#This Row],[Received]],"") -> 0 | H40: =IF(Over_all[[#This Row],[BOQ]]-Over_all[[#This Row],[Received]]<0,Over_all[[#This Row],[BOQ]]-Over_all[[#This Row],[Received]],"") | J40: =Over_all[[#This Row],[Received]] -> 0 | K40: =SUMIF(ISSUE!$F:$F,Over_all[[#This Row],[Item Description]],ISSUE!$I:$I) -> 0 | L40: =Over_all[[#This Row],[Received.]]-Over_all[[#This Row],[Issued]] -> 0
... A145: =BOQ[[#This Row],[S.No]] -> 9 | B145: =BOQ[[#This Row],[Item Description]] -> SS-304 (M12x80(SS-304-80mm L | C145: =BOQ[[#This Row],[Make / Vendor]] -> 0 | D145: =BOQ[[#This Row],[Unit]] -> Set | E145: =BOQ[[#This Row],[BOQ]] -> 440 | F145: =SUMIF('Goods Receipt'!$J:$J,Over_all[[#This Row],[Item Description]],'Goods Receipt'!$M:$M) -> 440 | G145: =IF(Over_all[[#This Row],[BOQ]]-Over_all[[#This Row],[Received]]>=0,Over_all[[#This Row],[BOQ]]-Over_all[[#This Row],[Received]],"") -> 0 | H145: =IF(Over_all[[#This Row],[BOQ]]-Over_all[[#This Row],[Received]]<0,Over_all[[#This Row],[BOQ]]-Over_all[[#This Row],[Received]],"") | J145: =Over_all[[#This Row],[Received]] -> 440 | K145: =SUMIF(ISSUE!$F:$F,Over_all[[#This Row],[Item Description]],ISSUE!$I:$I) -> 308 | L145: =Over_all[[#This Row],[Received.]]-Over_all[[#This Row],[Issued]] -> 132
A146: 10 | B146: =BOQ[[#This Row],[Item Description]] -> SS-304 (M10x80(SS-304-80mm L | C146: =BOQ[[#This Row],[Make / Vendor]] -> 0 | D146: =BOQ[[#This Row],[Unit]] -> Set | E146: =BOQ[[#This Row],[BOQ]] -> 352 | F146: =SUMIF('Goods Receipt'!$J:$J,Over_all[[#This Row],[Item Description]],'Goods Receipt'!$M:$M) -> 352 | G146: =IF(Over_all[[#This Row],[BOQ]]-Over_all[[#This Row],[Received]]>=0,Over_all[[#This Row],[BOQ]]-Over_all[[#This Row],[Received]],"") -> 0 | H146: =IF(Over_all[[#This Row],[BOQ]]-Over_all[[#This Row],[Received]]<0,Over_all[[#This Row],[BOQ]]-Over_all[[#This Row],[Received]],"") | J146: =Over_all[[#This Row],[Received]] -> 352 | K146: =SUMIF(ISSUE!$F:$F,Over_all[[#This Row],[Item Description]],ISSUE!$I:$I) -> 176 | L146: =Over_all[[#This Row],[Received.]]-Over_all[[#This Row],[Issued]] -> 176
A147: 11 | B147: =BOQ[[#This Row],[Item Description]] -> SDS with EPDM washer | C147: =BOQ[[#This Row],[Make / Vendor]] -> 0 | D147: =BOQ[[#This Row],[Unit]] -> Nos | E147: =BOQ[[#This Row],[BOQ]] -> 440 | F147: =SUMIF('Goods Receipt'!$J:$J,Over_all[[#This Row],[Item Description]],'Goods Receipt'!$M:$M) -> 440 | G147: =IF(Over_all[[#This Row],[BOQ]]-Over_all[[#This Row],[Received]]>=0,Over_all[[#This Row],[BOQ]]-Over_all[[#This Row],[Received]],"") -> 0 | H147: =IF(Over_all[[#This Row],[BOQ]]-Over_all[[#This Row],[Received]]<0,Over_all[[#This Row],[BOQ]]-Over_all[[#This Row],[Received]],"") | J147: =Over_all[[#This Row],[Received]] -> 440 | K147: =SUMIF(ISSUE!$F:$F,Over_all[[#This Row],[Item Description]],ISSUE!$I:$I) -> 220 | L147: =Over_all[[#This Row],[Received.]]-Over_all[[#This Row],[Issued]] -> 220
A148: =BOQ[[#This Row],[S.No]] -> 0 | B148: =BOQ[[#This Row],[Item Description]] -> 0 | C148: =BOQ[[#This Row],[Make / Vendor]] -> 0 | D148: =BOQ[[#This Row],[Unit]] -> 0 | E148: =BOQ[[#This Row],[BOQ]] -> 0 | F148: =SUMIF('Goods Receipt'!$J:$J,Over_all[[#This Row],[Item Description]],'Goods Receipt'!$M:$M) -> 0 | G148: =IF(Over_all[[#This Row],[BOQ]]-Over_all[[#This Row],[Received]]>=0,Over_all[[#This Row],[BOQ]]-Over_all[[#This Row],[Received]],"") -> 0 | H148: =IF(Over_all[[#This Row],[BOQ]]-Over_all[[#This Row],[Received]]<0,Over_all[[#This Row],[BOQ]]-Over_all[[#This Row],[Received]],"") | J148: =Over_all[[#This Row],[Received]] -> 0 | K148: =SUMIF(ISSUE!$F:$F,Over_all[[#This Row],[Item Description]],ISSUE!$I:$I) -> 0 | L148: =Over_all[[#This Row],[Received.]]-Over_all[[#This Row],[Issued]] -> 0
A149: =BOQ[[#This Row],[S.No]] -> J | B149: =BOQ[[#This Row],[Item Description]] -> Connectors | C149: =BOQ[[#This Row],[Make / Vendor]] -> 0 | D149: =BOQ[[#This Row],[Unit]] -> 0 | E149: =BOQ[[#This Row],[BOQ]] -> 0 | F149: =SUMIF('Goods Receipt'!$J:$J,Over_all[[#This Row],[Item Description]],'Goods Receipt'!$M:$M) -> 0 | G149: =IF(Over_all[[#This Row],[BOQ]]-Over_all[[#This Row],[Received]]>=0,Over_all[[#This Row],[BOQ]]-Over_all[[#This Row],[Received]],"") -> 0 | H149: =IF(Over_all[[#This Row],[BOQ]]-Over_all[[#This Row],[Received]]<0,Over_all[[#This Row],[BOQ]]-Over_all[[#This Row],[Received]],"") | J149: =Over_all[[#This Row],[Received]] -> 0 | K149: =SUMIF(ISSUE!$F:$F,Over_all[[#This Row],[Item Description]],ISSUE!$I:$I) -> 0 | L149: =Over_all[[#This Row],[Received.]]-Over_all[[#This Row],[Issued]] -> 0
A150: =BOQ[[#This Row],[S.No]] -> 0 | B150: =BOQ[[#This Row],[Item Description]] -> 0 | C150: =BOQ[[#This Row],[Make / Vendor]] -> 0 | D150: =BOQ[[#This Row],[Unit]] -> 0 | E150: =BOQ[[#This Row],[BOQ]] -> 0 | F150: =SUMIF('Goods Receipt'!$J:$J,Over_all[[#This Row],[Item Description]],'Goods Receipt'!$M:$M) -> 0 | G150: =IF(Over_all[[#This Row],[BOQ]]-Over_all[[#This Row],[Received]]>=0,Over_all[[#This Row],[BOQ]]-Over_all[[#This Row],[Received]],"") -> 0 | H150: =IF(Over_all[[#This Row],[BOQ]]-Over_all[[#This Row],[Received]]<0,Over_all[[#This Row],[BOQ]]-Over_all[[#This Row],[Received]],"") | J150: =Over_all[[#This Row],[Received]] -> 0 | K150: =SUMIF(ISSUE!$F:$F,Over_all[[#This Row],[Item Description]],ISSUE!$I:$I) -> 0 | L150: =Over_all[[#This Row],[Received.]]-Over_all[[#This Row],[Issued]] -> 0
A151: =BOQ[[#This Row],[S.No]] -> K | B151: =BOQ[[#This Row],[Item Description]] -> Cable_Glands | C151: =BOQ[[#This Row],[Make / Vendor]] -> 0 | D151: =BOQ[[#This Row],[Unit]] -> 0 | E151: =BOQ[[#This Row],[BOQ]] -> 0 | F151: =SUMIF('Goods Receipt'!$J:$J,Over_all[[#This Row],[Item Description]],'Goods Receipt'!$M:$M) -> 0 | G151: =IF(Over_all[[#This Row],[BOQ]]-Over_all[[#This Row],[Received]]>=0,Over_all[[#This Row],[BOQ]]-Over_all[[#This Row],[Received]],"") -> 0 | H151: =IF(Over_all[[#This Row],[BOQ]]-Over_all[[#This Row],[Received]]<0,Over_all[[#This Row],[BOQ]]-Over_all[[#This Row],[Received]],"") | J151: =Over_all[[#This Row],[Received]] -> 0 | K151: =SUMIF(ISSUE!$F:$F,Over_all[[#This Row],[Item Description]],ISSUE!$I:$I) -> 0 | L151: =Over_all[[#This Row],[Received.]]-Over_all[[#This Row],[Issued]] -> 0
A152: =BOQ[[#This Row],[S.No]] -> 1 | B152: =BOQ[[#This Row],[Item Description]] -> 3C X 240 Sq.mm Double Compression Metal Gland | C152: =BOQ[[#This Row],[Make / Vendor]] -> 0 | D152: =BOQ[[#This Row],[Unit]] -> Nos | E152: =BOQ[[#This Row],[BOQ]] -> 47 | F152: =SUMIF('Goods Receipt'!$J:$J,Over_all[[#This Row],[Item Description]],'Goods Receipt'!$M:$M) -> 47 | G152: =IF(Over_all[[#This Row],[BOQ]]-Over_all[[#This Row],[Received]]>=0,Over_all[[#This Row],[BOQ]]-Over_all[[#This Row],[Received]],"") -> 0 | H152: =IF(Over_all[[#This Row],[BOQ]]-Over_all[[#This Row],[Received]]<0,Over_all[[#This Row],[BOQ]]-Over_all[[#This Row],[Received]],"") | J152: =Over_all[[#This Row],[Received]] -> 47 | K152: =SUMIF(ISSUE!$F:$F,Over_all[[#This Row],[Item Description]],ISSUE!$I:$I) -> 0 | L152: =Over_all[[#This Row],[Received.]]-Over_all[[#This Row],[Issued]] -> 47
A153: =BOQ[[#This Row],[S.No]] -> 2 | B153: =BOQ[[#This Row],[Item Description]] -> 3C X 240 Sq.mm Double Bracing Metal Gland | C153: =BOQ[[#This Row],[Make / Vendor]] -> 0 | D153: =BOQ[[#This Row],[Unit]] -> Nos | E153: =BOQ[[#This Row],[BOQ]] -> 16 | F153: =SUMIF('Goods Receipt'!$J:$J,Over_all[[#This Row],[Item Description]],'Goods Receipt'!$M:$M) -> 16 | G153: =IF(Over_all[[#This Row],[BOQ]]-Over_all[[#This Row],[Received]]>=0,Over_all[[#This Row],[BOQ]]-Over_all[[#This Row],[Received]],"") -> 0 | H153: =IF(Over_all[[#This Row],[BOQ]]-Over_all[[#This Row],[Received]]<0,Over_all[[#This Row],[BOQ]]-Over_all[[#This Row],[Received]],"") | J153: =Over_all[[#This Row],[Received]] -> 16 | K153: =SUMIF(ISSUE!$F:$F,Over_all[[#This Row],[Item Description]],ISSUE!$I:$I) -> 0 | L153: =Over_all[[#This Row],[Received.]]-Over_all[[#This Row],[Issued]] -> 16
A154: =BOQ[[#This Row],[S.No]] -> 3 | B154: =BOQ[[#This Row],[Item Description]] -> 3C X 35 Sq.mm Double Bracing Metal Gland | C154: =BOQ[[#This Row],[Make / Vendor]] -> 0 | D154: =BOQ[[#This Row],[Unit]] -> Nos | E154: =BOQ[[#This Row],[BOQ]] -> 6 | F154: =SUMIF('Goods Receipt'!$J:$J,Over_all[[#This Row],[Item Description]],'Goods Receipt'!$M:$M) -> 6 | G154: =IF(Over_all[[#This Row],[BOQ]]-Over_all[[#This Row],[Received]]>=0,Over_all[[#This Row],[BOQ]]-Over_all[[#This Row],[Received]],"") -> 0 | H154: =IF(Over_all[[#This Row],[BOQ]]-Over_all[[#This Row],[Received]]<0,Over_all[[#This Row],[BOQ]]-Over_all[[#This Row],[Received]],"") | J154: =Over_all[[#This Row],[Received]] -> 6 | K154: =SUMIF(ISSUE!$F:$F,Over_all[[#This Row],[Item Description]],ISSUE!$I:$I) -> 0 | L154: =Over_all[[#This Row],[Received.]]-Over_all[[#This Row],[Issued]] -> 6
...

Sheet Master Data
B2: Category | D2: Unit | F2: Assets | G2: Battery | H2: Bus_Duct | I2: Cable_Tray | J2: DC_Cables | K2: AC_Cables | L2: HT_Cables | M2: Earthing_cables | N2: Aux_Control_Cable | O2: Communication_Cable | P2: CCTV | Q2: UPS | R2: MCS | S2: Connectors | T2: Cable_Glands | U2: Cable_Termination_Kit | V2: Cable_Lugs | W2: Cable_Sleeve | X2: Cable_Route_Marker | Y2: Cable_Tie | Z2: Inverter | AA2: Transformers | AB2: HT_Panel | AC2: LT_Panel | AD2: Aux_UPS_Panel | AE2: Earthing | AF2: Pheriperal Boundary | AG2: Inverters_Structure | AH2: Lighting_arrestor | AI2: Street_Light | AJ2: Module_Mounting_Structure | AK2: MMS_Fasteners | AL2: NIFPS | AM2: Pipes | AN2: Solar_Modules | AO2: Safety_Equipments | AP2: Others | AQ2: Switch Yard_Equipments With Accessories | AR2: Scada
B3: Billable | D3: Nos | F3: Store Container | H3: 5000A TP Air Insulated Bus duct Stright Run | J3: DC Cable | K3: 3CX240Sqmm A2XFY UNSCR ATR UV AF 3.3 KV | L3: 3CX240Sqmm A2XFY 19/33KV HT Cable | M3: 1C X 50Sq.mm Copper Flexible Cable | N3: 3C X 35Sq.mm 1.1 Kv A2XFY Cable | O3: CAT-6 Cable | R3: UPVC Pipe 11/2'' | T3: 3C X 240 Sq.mm Double Compression Metal Gland | U3: 3C X 240 Sq.mm Indoor Typr Termination Kit | V3: 3C X 240 Sq.mm Bi Metallic Lug | W3: 3C X 240 Sq.mm Cable Heat Sleeve Red | X3: LT Cable Route Marker | Y3: 100X2.5MM UV Cable Tie Black | Z3: Solis 225K-EHV-5G Plus Grid Tie Solar PV Inverter | AA3: 6 MVA Transformer | AB3: 33KV HT VCB Panel | AC3: 800V LT Panel | AD3: AUX ACDB Panel | AE3: 25x3 MM GI Earth Strip | AF3: Precast Panel | AG3: Inverter Column Post (ISMC - 100x50x5mm - 3000mmL | AH3: ESE Train | AI3: NES-SL-30 | AJ3: Column Post - 120x50x20x2.0 MM | AK3: HEX BOLT+NUT+2PLN WSR+1SP WSR M-16x40 | AL3: N2 Fire Production System | AM3: 38x50 OD DWC Pipe (500MTR) UV & Anti Rodent) | AO3: Sand Bucket With Stend canopy | AP3: Yellow Warning Tape (LT 2500 Mtr,DC 1000 Mtr,HT 500 Mtr) | AQ3: 66Kv CT For Metering | AR3: MCR Panel
B4: Non-Billable | D4: Mtr | F4: Secucity Cabin | H4: 5000A Copper Flexible (Traafo.End ) | J4: 1CX6Sqmm DC Cable Black | N4: 4C X 6Sq.mm 1.1 Kv A2XWY Cable | O4: RS 485 ARM Cable | R4: UPVC Pipe 1'' | T4: 3C X 240 Sq.mm Double Bracing Metal Gland | V4: 3C X 240Sq.mm Aluminium Lug | W4: 3C X 240 Sq.mm Cable Heat Sleeve Yellow | X4: HT Cable Route Marker | Y4: 300X4.8MM UV Cable Tie Black | AA4: Radiators | AB4: 33KV HT VCB Panel (21C-1OG) Board Panel | AD4: UPS Panel | AE4: 50x6 MM GI Earth Strip | AF4: Precast Post | AG4: Inverter Support Pipe (SHS-40x40x2.5mm-1550mmL | AH4: 6MM Guy Rope | AI4: 6.5 Mtr HDGI Street Light Pole | AJ4: Column Ext - 50x50x2.0 MM | AK4: HEX BOLT+NUT+2PLN WSR+1SP WSR M-10x30 | AL4: Fire Extingushing Cubicle | AM4: 50 MM Coupler | AO4: CO2 Type Fire Extinguisher - 4.5 Kg | AP4: 300mm AL Rail | AQ4: 66Kv CT For Protection -Ratio 100-150/1-1-1A | AR4: ICR Panel
B5: Consumables | D5: Kg | H5: 5000A Aluminium Flexible ( Panel End ) | J5: 1CX6Sqmm DC Cable Red | N5: 2C X 6Sq.mm Flexible HRFR Cable | O5: 12F FO Cable | R5: Gardan Pipe | T5: 3C X 35 Sq.mm Double Bracing Metal Gland | V5: 1C X 50Sq.mm Copper Lug | W5: 3C X 240 Sq,mm Cable Heat Sleeve Bule | X5: DC Cable Route Marker | Y5: 300x4.6 SS Cable Tie | AA5: Marshalling Box | AE5: 40x6 MM Copper Earth Strip | AG5: Roof Support -1 (ISA 40x40x5mm - 600mm L | AH5: 6MM U Clamp | AI5: NES-SL-70 | AJ5: Module Mounting Strucyure - Purlin (P1) | AK5: HEX BOLT+NUT+2PLN WSR+1SP WSR M-12x30 | AL5: Control Box | AM5: 50 MM Elbow | AO5: CO2 Type Fire Extinguisher - 9 Kg | AP5: Portr.High | AQ5: 66Kv CT For Protection -Ratio 300-600/1-1-1-A | AR5: Operating Work Station With Pre Installation Software and keyboard &Mouse
B6: Safety | D6: Set | H6: Bus Duct Accessories | N6: 2C X 4Sq.mm Copper Flexible Cable | R6: UPVC Vall 1 1/2 | T6: 2C X 6 Sq.mm Double Bracing Metal Gland | V6: 4.0 Sq.mm Cu Ring Type Lug | W6: 50 Sq.mm Cable Heat Sleeve | AA6: Conservator Tank With Accessories | AG6: Roof Support -2 (ISA 40x40x5mm - 700mm L | AH6: Grount Hook for fixing guy cable | AI6: ARM Bracket | AJ6: Module Mounting Strucyure - Rafter | AK6: HEX BOLT+NUT+REC.WSR+ 1SP WSR M-10x30 | AL6: Fire Detectors | AM6: 50 MM Tee | AO6: ABC Type Fire Extinguisher - 6 Kg | AP6: PU Form | AQ6: 66Kv CT For Metering -Ratio of 100/1A | AR6: 32 Inch Display
B7: Tools and Tackles | D7: Lot | N7: 2C X 2.5 Sq.mm Copper Flexible Cable | R7: UPVC Vall 1 | T7: 4C X 6 Sq.mm Double Bracing Metal Gland | V7: 1C X 4.0 Sq.mm Cu Copper Lug | W7: 2C X 6 Sq.mm Cable Heat Sleeve | AA7: HV Cable Box & HV Cable Box Canopy Fitted | AG7: Roof Support -3 (ISA 40x40x5mm - 644mm L | AH7: J bolt (dia 18x500mm) for fixing mast base plate hole | AI7: Conduict | AJ7: Module Mounting Strucyure - Rafter Bracing Back | AK7: Rectangle Washer (40*20*11*3) Mechanical Plating | AL7: Signal Box | AM7: 50 MM O Ring | AO7: Safety Shoes (Allen copper-1156) | AP7: Cable Tag | AQ7: 66Kv PT For Metering 66kv/RT3/110V/RT3 | AR7: A4 Printer
B8: Assets | D8: Ltr | N8: 12C X 2.5 Sq.mm 1.1 Kv 2XFY Cable | R8: UPVC Elbow 1 1/2 | T8: 2C X 4.0 Sq.mm PVC Gland | V8: 35 Sq.mm Al Ring Type Lug | W8: 2C X 4 Sq.mm Cable Heat Sleeve | AA8: 33Kv Insulators | AG8: Purlin (SHA-30x30x2.5mm - 2200mm L | AH8: Down Conductor insulator BC 525 with nut bolt | AI8: Rod | AJ8: Module Mounting Strucyure - Bracing Connector | AK8: Hex Bolt,M8x20 | AL8: Transformer Conservator Isolation Valve | AM8: Np3 600 MM S&S Pipe | AO8: Safety Shoes (Labour) | AP8: Scada MCR | AQ8: 66Kv CT For Metering -200/1A | AR8: Wooden Table
B9: Others | D9: Coil | N9: 3C X 4 Sq.mm Copper Flexible Cable | R9: UPVC Elbow 1 | T9: 2C X 2.5 Sq.mm PVC Gland | V9: 2.5 Sq.mm Cu Ring Type Lug | W9: 4C X 6 Sq.mm Cable Heat Sleeve | AA9: Aluminium Gland Plate | AG9: Conduit Support Pipe (SHS-40x40x2.5mm - 1550mm L | AH9: OTC 25x3 | AI9: Junction Box | AJ9: Module Mounting Strucyure - Purlin (P2) | AK9: Hex Nut,M8 | AL9: Keys | AO9: Safety Gumboot | AP9: Scada ICR 1 | AQ9: 66Kv PT For Metering 66kv/RT3/110V/RT3 | AR9: Chair
D10: Pair | R10: UPVC Tee 1 1/2 | T10: 12C X 2.5 Sq.mm PVC Gland | V10: 2.5 Sq.mm Cu Pin Type Lug | W10: 2C X 2.5 Sq.mm Cable Heat Sleeve | AA10: Inspection Cover | AG10: Roof Sheet (1200x2400x0.5mm) | AH10: L shape | AI10: 3C X 1.5 Sq mm Copper Flexible Cable | AJ10: Module Mounting Strucyure - Col, to Rafter Bracing front | AK10: Plain WSR,M8 | AL10: FS Cable | AO10: Safety Relflectice Jacket Staff | AP10: Scada ICR 2 | AQ10: 66Kv Control & Relay Panel | AR10: SC-LC Patch Cord Single Mode
R11: UPVC Tee 1 | V11: 2.5 Sq.mm Cu Fork Type Lug | W11: 12 X 2.5 Sq.mm Cable Heat Sleeve | AA11: 50 X 06 mm Copper Flat | AG11: SS-304 (M12x80(SS-304-80mm L | AH11: Lightning flash counter | AI11: LED Arm | AJ11: Module Mounting Strucyure - Stay Bracing | AK11: Spring WSRM8 | AL11: Fire Detectors Cover | AO11: Safety Relflectice Jacket Orange | AP11: Radium Stickers 200 X 60 | AQ11: Switch Yard Materials & Structure & Structure Fasteners
R12: UPVC Redusar | V12: 6 Sq.mm Fork Type Copper Lug | AA12: Danger Plate | AG12: SS-304 (M10x80(SS-304-80mm L | AH12: GI supporting mast of 7 mtrs in 3 parts with base plate | AK12: M8 Serrated Washer | AL12: FRLS 12 Core Cable | AO12: Safety Helmet | AP12: Radium Stickers 300 X 60
R13: UPVC Redusar Tee | V13: 6 Sq.mm AL Ring Type Lug | AA13: Breather | AG13: SDS with EPDM washer | AH13: 17mm dia, 3mtr long copper bonded rod with clamp with nut and bolt,plain & spring | AL13: FRLS 4 Core Cable | AO13: Safety Helmet Green
B14: Sub-contractor Name | D14: Price | R14: UPVC Coplin 1 1/2 | V14: 6 Sq.mm Cu Pin Type Lug | AA14: Buchholz Relay & Buchholz Canopy | AH14: Earthcon | AL14: Supply of Pipe Fittings | AO14: Safety Helmet labour
B15: Inqilab | D15: Show | R15: UPVC Coplin 1 | V15: 16 Sq.mm Ring Type Lug | AA15: 450mm / 132w / 900 rpm With Wire Guard For Fan | AL15: Pipes For connection Between | AO15: Safety Hand Gloves (White Grey)
B16: Udaratva | D16: Hide | R16: UPVC Handcap 1 1/2 | AA16: Transformer Oil | AL16: 6'' GI Pipe -6Mtr Iength | AO16: Safety Hand Gloves Lether For Welding
R17: UPVC Handcap 1 | AO17: Safety Goggles
R18: Taki | AO18: Safety (Barrication Tap Roll)
R19: Motor | AO19: Full Body Harness With Soak Absorber
R20: Soket Set | AO20: Stretcher Foldable
R21: Preser Vall | AO21: First And Box
R22: NRV Vall 1 1/2 | AO22: Snack Cather Stick
R23: UPVC Union 1 1/2 | AO23: Safety Welding Helmat
AO24: CO2 Fire Extinguisher - 4.5Kg
AO25: Abc Type Fire Extinguisher - 4 Kg
AO26: Safety Fire Stand With 4 Buckets
AO27: Digital vernier caliper
AO28: Coating Thickness Tester
AO29: Earth Testing Kit
AO30: LOTO Kit
B31: Location | AO31: 5Kv Meco Make Megger
B32: Block-1 | AO32: 2000V AC/DC Clamp Meter -Meco
B33: PSS | AO33: Measuring Tap-5 MTR
AO34: Jacket &Bib pant,Hood,Class E Helmet With Face Shield ,Fabric Leathergloves and storage Bag
AO35: Screw Driver (Taparia)
AO36: Sprit Level
AO37: 33Kv Earthing Electrode

Sheet ISSUE
A2: S. No. | B2: Req Slip No. | C2: Date | D2: Item Category | E2: Item Types | F2: Item Description | G2: Unit | H2: Quantity Demanded | I2: Quantity Issued | J2: Sub-contractor Name | K2: Contractor Person (Received by) | L2: Location | M2: Recommanded Engineer (Name) | N2: Issued By | O2: Remarks
A3: 1 | B3: 5251 | C3: 45569 | D3: Billable | E3: MMS_Fasteners | F3: HEX BOLT+NUT+2PLN WSR+1SP WSR M-10x30 | G3: Set | H3: 0 | I3: 0 | J3: New Aditya | K3: Jay-Patel | L3: Phase 02 | M3: Sadham | N3: Sundar | O3: 1050 Return
A4: =+A3+1 -> 2 | B4: 5253 | C4: 45585 | D4: Billable | E4: Module_Mounting_Structure | F4: Column Post - 120x50x20x2.0 MM | G4: Nos | H4: 519 | I4: 519 | J4: Inqilab | K4: Piyush | L4: Phase 02 | M4: Sadham | N4: Sundar
A5: =+A4+1 -> 3 | B5: 5253 | C5: 45585 | D5: Billable | E5: Module_Mounting_Structure | F5: Column Ext - 50x50x2.0 MM | G5: Nos | H5: 498 | I5: 498 | J5: Inqilab | K5: Piyush | L5: Phase 02 | M5: Sadham | N5: Sundar
A6: 4 | B6: 5253 | C6: 45585 | D6: Billable | E6: MMS_Fasteners | F6: HEX BOLT+NUT+2PLN WSR+1SP WSR M-10x30 | G6: Set | H6: 2370 | I6: 2370 | J6: Inqilab | K6: Piyush | L6: Phase 02 | M6: Sadham | N6: Sundar
A7: =+A6+1 -> 5 | B7: 5254 | C7: 45589 | D7: Billable | E7: MMS_Fasteners | F7: HEX BOLT+NUT+2PLN WSR+1SP WSR M-10x30 | G7: Set | H7: 1600 | I7: 1600 | J7: Inqilab | K7: Piyush | L7: Phase 02 | M7: Sadham | N7: Sundar
A8: 6 | B8: 5255 | C8: 45590 | D8: Billable | E8: MMS_Fasteners | F8: HEX BOLT+NUT+2PLN WSR+1SP WSR M-10x30 | G8: Set | H8: 1050 | I8: 1050 | J8: Udaratva | K8: Venugopal | L8: Phase 02 | M8: Sadham | N8: Sundar
A9: 7 | B9: 5256 | C9: 45590 | D9: Billable | E9: Safety_Equipments | F9: Safety Shoes (Labour) | G9: Set | H9: 4 | I9: 4 | J9: Udaratva | K9: Venugopal | L9: Phase 02 | M9: Sadham | N9: Sundar
A10: 8 | B10: 5257 | C10: 45590 | D10: Billable | E10: Inverters_Structure | F10: Inverter Column Post (ISMC - 100x50x5mm - 3000mmL | G10: Nos | H10: 22 | I10: 22 | J10: Inqilab | K10: Piyush | L10: Phase 02 | M10: Sadham | N10: Sundar
A11: 9 | B11: 5257 | C11: 45590 | D11: Billable | E11: Inverters_Structure | F11: SS-304 (M12x80(SS-304-80mm L | G11: Set | H11: 88 | I11: 88 | J11: Inqilab | K11: Piyush | L11: Phase 02 | M11: Sadham | N11: Sundar
A12: 10 | B12: 5258 | C12: 45605 | D12: Billable | E12: Module_Mounting_Structure | F12: Column Post - 120x50x20x2.0 MM | G12: Nos | H12: 1000 | I12: 1000 | J12: Udaratva | K12: Venugopal | L12: Phase 02 | M12: Sadham | N12: Sundar
A13: 11 | B13: 5258 | C13: 45605 | D13: Billable | E13: Module_Mounting_Structure | F13: Column Ext - 50x50x2.0 MM | G13: Nos | H13: 1000 | I13: 1000 | J13: Udaratva | K13: Venugopal | L13: Phase 02 | M13: Sadham | N13: Sundar
A14: 12 | B14: 5259 | C14: 45605 | D14: Billable | E14: Module_Mounting_Structure | F14: Column Post - 120x50x20x2.0 MM | G14: Nos | H14: 1030 | I14: 1030 | J14: Inqilab | K14: Piyush | L14: Phase 02 | M14: Sadham | N14: Sundar
A15: 13 | B15: 5259 | C15: 45605 | D15: Billable | E15: Module_Mounting_Structure | F15: Column Ext - 50x50x2.0 MM | G15: Nos | H15: 1030 | I15: 1030 | J15: Inqilab | K15: Piyush | L15: Phase 02 | M15: Sadham | N15: Sundar
A16: 14 | B16: 5259 | C16: 45605 | D16: Billable | E16: MMS_Fasteners | F16: HEX BOLT+NUT+2PLN WSR+1SP WSR M-10x30 | G16: Set | H16: 2150 | I16: 2150 | J16: Inqilab | K16: Piyush | L16: Phase 02 | M16: Sadham | N16: Sundar
A17: 15 | B17: 5260 | C17: 45605 | D17: Billable | E17: Safety_Equipments | F17: Safety Shoes (Allen copper-1156) | G17: Set | H17: 1 | I17: 1 | K17: Birjesh Panchal | L17: Phase 02 | M17: Sadham | N17: Sundar | O17: Cilent
A18: 16 | B18: 5261 | C18: 45605 | D18: Billable | E18: Safety_Equipments | F18: Safety Shoes (Allen copper-1156) | G18: Set | H18: 1 | I18: 1 | K18: Prince | L18: Phase 02 | M18: Sadham | N18: Sundar | O18: Prozeal/O/M
A19: 17 | B19: 5262 | C19: 45605 | D19: Billable | E19: Safety_Equipments | F19: Safety Shoes (Allen copper-1156) | G19: Set | H19: 1 | I19: 1 | K19: Sunil Kumar | L19: Phase 02 | M19: Sadham | N19: Sundar | O19: Prozeal Q/C
A20: 18 | B20: 5262 | C20: 45605 | D20: Billable | E20: Safety_Equipments | F20: Safety Relflectice Jacket Staff | G20: Nos | H20: 1 | I20: 1 | K20: Sunil Kumar | L20: Phase 02 | M20: Sadham | N20: Sundar | O20: Prozeal Q/C
A21: 19 | B21: 5262 | C21: 45605 | D21: Billable | E21: Safety_Equipments | F21: Safety Helmet | G21: Nos | H21: 1 | I21: 1 | K21: Sunil Kumar | L21: Phase 02 | M21: Sadham | N21: Sundar | O21: Prozeal Q/C
A22: 20 | B22: 5263 | C22: 45609 | D22: Billable | E22: MMS_Fasteners | F22: HEX BOLT+NUT+2PLN WSR+1SP WSR M-10x30 | G22: Set | H22: 2100 | I22: 2100 | J22: Udaratva | K22: Venugopal | L22: Phase 02 | M22: Sadham | N22: Sundar
A23: 21 | B23: 5264 | C23: 45609 | D23: Billable | E23: Module_Mounting_Structure | F23: Module Mounting Strucyure - Rafter | G23: Nos | H23: 1090 | I23: 1090 | J23: Inqilab | K23: Piyush | L23: Phase 02 | M23: Sadham | N23: Sundar
A24: =+A23+1 -> 22 | B24: 5264 | C24: 45609 | D24: Billable | E24: Module_Mounting_Structure | F24: Module Mounting Strucyure - Col, to Rafter Bracing front | G24: Nos | H24: 1090 | I24: 1090 | J24: Inqilab | K24: Piyush | L24: Phase 02 | M24: Sadham | N24: Sundar
A25: =+A24+1 -> 23 | B25: 5264 | C25: 45609 | D25: Billable | E25: Module_Mounting_Structure | F25: Module Mounting Strucyure - Rafter Bracing Back | G25: Nos | H25: 1090 | I25: 1090 | J25: Inqilab | K25: Piyush | L25: Phase 02 | M25: Sadham | N25: Sundar
A26: =+A25+1 -> 24 | B26: 5264 | C26: 45609 | D26: Billable | E26: MMS_Fasteners | F26: Hex Bolt,M8x20 | G26: Nos | H26: 1510 | I26: 1510 | J26: Inqilab | K26: Piyush | L26: Phase 02 | M26: Sadham | N26: Sundar
A27: =+A26+1 -> 25 | B27: 5264 | C27: 45609 | D27: Billable | E27: MMS_Fasteners | F27: Hex Nut,M8 | G27: Nos | H27: 1510 | I27: 1510 | J27: Inqilab | K27: Piyush | L27: Phase 02 | M27: Sadham | N27: Sundar
A28: =+A27+1 -> 26 | B28: 5264 | C28: 45609 | D28: Billable | E28: MMS_Fasteners | F28: Plain WSR,M8 | G28: Nos | H28: 16302 | I28: 16302 | J28: Inqilab | K28: Piyush | L28: Phase 02 | M28: Sadham | N28: Sundar
A29: =+A28+1 -> 27 | B29: 5264 | C29: 45609 | D29: Billable | E29: MMS_Fasteners | F29: Spring WSRM8 | G29: Nos | H29: 21510 | I29: 21510 | J29: Inqilab | K29: Piyush | L29: Phase 02 | M29: Sadham | N29: Sundar
A30: =+A29+1 -> 28 | B30: 5265 | C30: 45611 | D30: Billable | E30: MMS_Fasteners | F30: HEX BOLT+NUT+2PLN WSR+1SP WSR M-10x30 | G30: Set | H30: 3500 | I30: 3500 | J30: Udaratva | K30: Venugopal | L30: Phase 02 | M30: Sadham | N30: Sundar
A31: =+A30+1 -> 29 | B31: 5265 | C31: 45611 | D31: Billable | E31: MMS_Fasteners | F31: HEX BOLT+NUT+2PLN WSR+1SP WSR M-12x30 | G31: Set | H31: 3750 | I31: 3750 | J31: Udaratva | K31: Venugopal | L31: Phase 02 | M31: Sadham | N31: Sundar
A32: =+A31+1 -> 30 | B32: 5265 | C32: 45611 | D32: Billable | E32: MMS_Fasteners | F32: HEX BOLT+NUT+2PLN WSR+1SP WSR M-16x40 | G32: Set | H32: 1000 | I32: 1000 | J32: Udaratva | K32: Venugopal | L32: Phase 02 | M32: Sadham | N32: Sundar
A33: =+A32+1 -> 31 | B33: 5265 | C33: 45611 | D33: Billable | E33: MMS_Fasteners | F33: HEX BOLT+NUT+REC.WSR+ 1SP WSR M-10x30 | G33: Set | H33: 5000 | I33: 5000 | J33: Udaratva | K33: Venugopal | L33: Phase 02 | M33: Sadham | N33: Sundar
A34: =+A33+1 -> 32 | B34: 5265 | C34: 45611 | D34: Billable | E34: Inverters_Structure | F34: Inverter Column Post (ISMC - 100x50x5mm - 3000mmL | G34: Nos | H34: 44 | I34: 44 | J34: Udaratva | K34: Venugopal | L34: Phase 02 | M34: Sadham | N34: Sundar
A35: =+A34+1 -> 33 | B35: 5265 | C35: 45611 | D35: Billable | E35: Inverters_Structure | F35: Inverter Support Pipe (SHS-40x40x2.5mm-1550mmL | G35: Nos | H35: 44 | I35: 44 | J35: Udaratva | K35: Venugopal | L35: Phase 02 | M35: Sadham | N35: Sundar
... A65: =+A64+1 -> 63 | B65: 5272 | C65: 45624 | D65: Billable | E65: Pipes | F65: 38x50 OD DWC Pipe (500MTR) UV & Anti Rodent) | G65: Mtr | H65: 1000 | I65: 1000 | J65: Inqilab | K65: Piyush | L65: Phase 02 | M65: Sadham | N65: Sundar
A66: =+A65+1 -> 64 | B66: 5272 | C66: 45624 | D66: Billable | E66: AC_Cables | F66: 3CX240Sqmm A2XFY UNSCR ATR UV AF 3.3 KV | G66: Mtr | H66: 1008 | I66: 1008 | J66: Inqilab | K66: Piyush | L66: Phase 02 | M66: Sadham | N66: Sundar | O66: Drum No:HT246599E24
A67: =+A66+1 -> 65 | B67: 5272 | C67: 45624 | D67: Billable | E67: AC_Cables | F67: 3CX240Sqmm A2XFY UNSCR ATR UV AF 3.3 KV | G67: Mtr | H67: 987 | I67: 987 | J67: Inqilab | K67: Piyush | L67: Phase 02 | M67: Sadham | N67: Sundar | O67: Drum No:HT46596E24
A68: =+A67+1 -> 66 | B68: 5272 | C68: 45624 | D68: Billable | E68: AC_Cables | F68: 3CX240Sqmm A2XFY UNSCR ATR UV AF 3.3 KV | G68: Mtr | H68: 1010 | I68: 1010 | J68: Inqilab | K68: Piyush | L68: Phase 02 | M68: Sadham | N68: Sundar | O68: Drum No: HT46597E24
A69: =+A68+1 -> 67 | B69: 5273 | C69: 45624 | D69: Billable | E69: Safety_Equipments | F69: Safety Gumboot | G69: Set | H69: 3 | I69: 3 | J69: Udaratva | K69: Venugopal | L69: Phase 02 | M69: Sadham | N69: Sundar | O69: Debit
A70: =+A69+1 -> 68 | B70: 5274 | C70: 45625 | D70: Billable | E70: MMS_Fasteners | F70: HEX BOLT+NUT+REC.WSR+ 1SP WSR M-10x30 | G70: Set | H70: 23960 | I70: 23960 | J70: Inqilab | K70: Piyush | L70: Phase 02 | M70: Sadham | N70: Sundar
...

Sheet Goods Receipt
A3: S. No. | B3: Recd. Date | C3: Vendor Invoice No | D3: Vendor Invoice Date | E3: GRN | F3: GRN Date | G3: Supplier Name | H3: Item Category | I3: Item Type | J3: Item Description | K3: Unit | L3: Invoice. / Received Qty | M3: Accepted Qty | N3: Rejected/ Shortage Qty. | O3: LR No. | P3: LR. Date | Q3: Transporter Name | R3: Vechicle No | S3: P O No. | T3: P O Date. | U3: Received Qty | V3: Purchase unit | W3: Purchase Rate | X3: Purchase Amount | Y3: WAY BILL No. | Z3: Remarks | AB3: Price | AC3: Show
A4: 1 | B4: 45499 | C4: NSM01169/2024-25 | D4: 45498 | E4: 2 | F4: 45519 | H4: Billable | I4: Module_Mounting_Structure | J4: Column Post - 120x50x20x2.0 MM | K4: Nos | L4: 2160 | M4: 2160 | N4: =Goods_Receipt[[#This Row],[ Invoice. / Received Qty ]]-Goods_Receipt[[#This Row],[ Accepted Qty ]] -> 0 | O4: 42 | P4: 45498 | R4: GJ06AX9564 | S4: PGEL/24-25/1219 | T4: 45468 | Y4: 671757801051
A5: 2 | B5: 45499 | C5: NSM01169/2024-25 | D5: 45498 | E5: 2 | F5: 45519 | H5: Billable | I5: Module_Mounting_Structure | J5: Column Ext - 50x50x2.0 MM | K5: Nos | L5: 2160 | M5: 2160 | N5: =Goods_Receipt[[#This Row],[ Invoice. / Received Qty ]]-Goods_Receipt[[#This Row],[ Accepted Qty ]] -> 0 | O5: 42 | P5: 45498 | R5: GJ06AX9564 | S5: PGEL/24-25/1219 | T5: 45468 | Y5: 671757801051
A6: 3 | B6: 45503 | C6: NGF/0468/24-25 | D6: 45497 | E6: 3 | F6: 45519 | H6: Billable | I6: MMS_Fasteners | J6: HEX BOLT+NUT+2PLN WSR+1SP WSR M-16x40 | K6: Nos | L6: 4290 | M6: 4290 | N6: =Goods_Receipt[[#This Row],[ Invoice. / Received Qty ]]-Goods_Receipt[[#This Row],[ Accepted Qty ]] -> 0 | O6: 3631 | P6: 45497 | R6: HR69D3182 | S6: PGEL/24-25/1406 | T6: 45476 | Y6: 241799438896
A7: 4 | B7: 45503 | C7: NGF/0468/24-25 | D7: 45497 | E7: 3 | F7: 45519 | H7: Billable | I7: MMS_Fasteners | J7: HEX BOLT+NUT+2PLN WSR+1SP WSR M-10x30 | K7: Nos | L7: 12870 | M7: 12870 | N7: =Goods_Receipt[[#This Row],[ Invoice. / Received Qty ]]-Goods_Receipt[[#This Row],[ Accepted Qty ]] -> 0 | O7: 3631 | P7: 45497 | R7: HR69D3182 | S7: PGEL/24-25/1406 | T7: 45476 | Y7: 241799438896
A8: 5 | B8: 45503 | C8: NGF/0468/24-25 | D8: 45497 | E8: 3 | F8: 45519 | H8: Billable | I8: MMS_Fasteners | J8: HEX BOLT+NUT+2PLN WSR+1SP WSR M-12x30 | K8: Nos | L8: 54340 | M8: 54340 | N8: =Goods_Receipt[[#This Row],[ Invoice. / Received Qty ]]-Goods_Receipt[[#This Row],[ Accepted Qty ]] -> 0 | O8: 3631 | P8: 45497 | R8: HR69D3182 | S8: PGEL/24-25/1406 | T8: 45476 | Y8: 241799438896
A9: 6 | B9: 45503 | C9: NGF/0468/24-25 | D9: 45497 | E9: 3 | F9: 45519 | H9: Billable | I9: MMS_Fasteners | J9: HEX BOLT+NUT+REC.WSR+ 1SP WSR M-10x30 | K9: Nos | L9: 57200 | M9: 57200 | N9: =Goods_Receipt[[#This Row],[ Invoice. / Received Qty ]]-Goods_Receipt[[#This Row],[ Accepted Qty ]] -> 0 | O9: 3631 | P9: 45497 | R9: HR69D3182 | S9: PGEL/24-25/1406 | T9: 45476 | Y9: 241799438896
A10: 7 | B10: 45504 | C10: 24-25/231 | D10: 45500 | E10: 4 | F10: 45519 | H10: Billable | I10: MMS_Fasteners | J10: Rectangle Washer (40*20*11*3) Mechanical Plating | K10: Nos | L10: 114400 | M10: 114400 | N10: =Goods_Receipt[[#This Row],[ Invoice. / Received Qty ]]-Goods_Receipt[[#This Row],[ Accepted Qty ]] -> 0 | O10: 231 | P10: 45500 | R10: GJ06BX3206 | Y10: 381818012077
A11: 8 | B11: 45512 | C11: NGF/0517/24-25 | D11: 45509 | E11: 5 | F11: 45519 | H11: Billable | I11: MMS_Fasteners | J11: Hex Bolt,M8x20 | K11: Nos | L11: 80000 | M11: 80000 | N11: =Goods_Receipt[[#This Row],[ Invoice. / Received Qty ]]-Goods_Receipt[[#This Row],[ Accepted Qty ]] -> 0 | O11: 948094 | P11: 45509 | R11: GJ06AZ8868 | S11: PGEL/24-25/1406 | T11: 45476 | Y11: 251805544671
A12: 9 | B12: 45512 | C12: NGF/0517/24-25 | D12: 45509 | E12: 5 | F12: 45519 | H12: Billable | I12: MMS_Fasteners | J12: Hex Bolt,M8x20 | K12: Nos | L12: 1510 | M12: 1510 | N12: =Goods_Receipt[[#This Row],[ Invoice. / Received Qty ]]-Goods_Receipt[[#This Row],[ Accepted Qty ]] -> 0 | O12: 948094 | P12: 45509 | R12: GJ06AZ8868 | S12: PGEL/24-25/1406 | T12: 45476 | Y12: 251805544671
A13: 10 | B13: 45512 | C13: NGF/0517/24-25 | D13: 45509 | E13: 5 | F13: 45519 | H13: Billable | I13: MMS_Fasteners | J13: Hex Nut,M8 | K13: Nos | L13: 1510 | M13: 1510 | N13: =Goods_Receipt[[#This Row],[ Invoice. / Received Qty ]]-Goods_Receipt[[#This Row],[ Accepted Qty ]] -> 0 | O13: 948094 | P13: 45509 | R13: GJ06AZ8868 | S13: PGEL/24-25/1406 | T13: 45476 | Y13: 251805544671
A14: 11 | B14: 45512 | C14: NGF/0517/24-25 | D14: 45509 | E14: 5 | F14: 45519 | H14: Billable | I14: MMS_Fasteners | J14: Hex Nut,M8 | K14: Nos | L14: 80000 | M14: 80000 | N14: =Goods_Receipt[[#This Row],[ Invoice. / Received Qty ]]-Goods_Receipt[[#This Row],[ Accepted Qty ]] -> 0 | O14: 948094 | P14: 45509 | R14: GJ06AZ8868 | S14: PGEL/24-25/1406 | T14: 45476 | Y14: 251805544671
A15: 12 | B15: 45512 | C15: NGF/0517/24-25 | D15: 45509 | E15: 5 | F15: 45519 | H15: Billable | I15: MMS_Fasteners | J15: Plain WSR,M8 | K15: Nos | L15: 163020 | M15: 163020 | N15: =Goods_Receipt[[#This Row],[ Invoice. / Received Qty ]]-Goods_Receipt[[#This Row],[ Accepted Qty ]] -> 0 | O15: 948094 | P15: 45509 | R15: GJ06AZ8868 | S15: PGEL/24-25/1406 | T15: 45476 | Y15: 251805544671
A16: 13 | B16: 45512 | C16: NGF/0517/24-25 | D16: 45509 | E16: 5 | F16: 45519 | H16: Billable | I16: MMS_Fasteners | J16: Spring WSRM8 | K16: Nos | L16: 40000 | M16: 40000 | N16: =Goods_Receipt[[#This Row],[ Invoice. / Received Qty ]]-Goods_Receipt[[#This Row],[ Accepted Qty ]] -> 0 | O16: 948094 | P16: 45509 | R16: GJ06AZ8868 | S16: PGEL/24-25/1406 | T16: 45476 | Y16: 251805544671
A17: 14 | B17: 45512 | C17: NGF/0517/24-25 | D17: 45509 | E17: 5 | F17: 45519 | H17: Billable | I17: MMS_Fasteners | J17: Spring WSRM8 | K17: Nos | L17: 41510 | M17: 41510 | N17: =Goods_Receipt[[#This Row],[ Invoice. / Received Qty ]]-Goods_Receipt[[#This Row],[ Accepted Qty ]] -> 0 | O17: 948094 | P17: 45509 | R17: GJ06AZ8868 | S17: PGEL/24-25/1406 | T17: 45476 | Y17: 251805544671
A18: 15 | B18: 45514 | D18: 45514 | E18: 31 | F18: 45519 | H18: Billable | I18: Inverter | J18: Solis 225K-EHV-5G Plus Grid Tie Solar PV Inverter | K18: Nos | L18: 3 | M18: 3 | N18: =Goods_Receipt[[#This Row],[ Invoice. / Received Qty ]]-Goods_Receipt[[#This Row],[ Accepted Qty ]] -> 0 | O18: 52422 | P18: 45514 | R18: GJ13AW0110 | S18: 4200052777 | T18: 45514 | Y18: 661765509003
A19: 16 | B19: 45514 | D19: 45514 | E19: 32 | F19: 45519 | H19: Billable | I19: Inverter | J19: Solis 225K-EHV-5G Plus Grid Tie Solar PV Inverter | K19: Nos | L19: 3 | M19: 3 | N19: =Goods_Receipt[[#This Row],[ Invoice. / Received Qty ]]-Goods_Receipt[[#This Row],[ Accepted Qty ]] -> 0 | O19: 52422 | P19: 45514 | R19: GJ13AW0110 | S19: 4200054306 | T19: 45514 | Y19: 661765509003
A20: 17 | B20: 45516 | C20: NSM01308/2024-25 | D20: 45514 | E20: 7 | F20: 45519 | H20: Billable | I20: Module_Mounting_Structure | J20: Module Mounting Strucyure - Purlin (P1) | K20: Nos | L20: 1799 | M20: 1799 | N20: =Goods_Receipt[[#This Row],[ Invoice. / Received Qty ]]-Goods_Receipt[[#This Row],[ Accepted Qty ]] -> 0 | O20: 46 | P20: 45514 | R20: GJ06BV5038 | S20: PGEL/24-25/1219 | T20: 45468 | Y20: 681765877331
